pipenv run gunicorn -w 4 -b 0.0.0.0:5003 sidekick_server:app
Creating a virtualenv for this project...
Pipfile: /home/markbur@ilab.local/sidekick/server/Pipfile
Using /usr/bin/python3.10 (3.10.11) to create virtualenv...
⠋ Creating virtual environment...
✘ Failed creating virtual environment 
[pipenv.exceptions.VirtualenvCreationException]: /usr/bin/python3: No module named virtualenv

Failed to create virtual environment.
make: *** [Makefile:16: run-prod-locally] Error 1
pipenv run gunicorn -w 4 -b 0.0.0.0:5003 sidekick_server:app
[2023-09-21 12:41:01 +0100] [1967798] [INFO] Starting gunicorn 21.2.0
[2023-09-21 12:41:01 +0100] [1967798] [INFO] Listening at: http://0.0.0.0:5003 (1967798)
[2023-09-21 12:41:01 +0100] [1967798] [INFO] Using worker: sync
[2023-09-21 12:41:01 +0100] [1967803] [INFO] Booting worker with pid: 1967803
[2023-09-21 12:41:01 +0100] [1967804] [INFO] Booting worker with pid: 1967804
[2023-09-21 12:41:01 +0100] [1967805] [INFO] Booting worker with pid: 1967805
[2023-09-21 12:41:01 +0100] [1967806] [INFO] Booting worker with pid: 1967806
[2023-09-21 12:41:01 +0100] [1967803] [ERROR] Exception in worker process
Traceback (most recent call last):
  File "/home/markbur@ilab.local/.local/share/virtualenvs/server-e9qqH9Aq/lib/python3.10/site-packages/gunicorn/arbiter.py", line 609, in spawn_worker
    worker.init_process()
  File "/home/markbur@ilab.local/.local/share/virtualenvs/server-e9qqH9Aq/lib/python3.10/site-packages/gunicorn/workers/base.py", line 134, in init_process
    self.load_wsgi()
  File "/home/markbur@ilab.local/.local/share/virtualenvs/server-e9qqH9Aq/lib/python3.10/site-packages/gunicorn/workers/base.py", line 146, in load_wsgi
    self.wsgi = self.app.wsgi()
  File "/home/markbur@ilab.local/.local/share/virtualenvs/server-e9qqH9Aq/lib/python3.10/site-packages/gunicorn/app/base.py", line 67, in wsgi
    self.callable = self.load()
  File "/home/markbur@ilab.local/.local/share/virtualenvs/server-e9qqH9Aq/lib/python3.10/site-packages/gunicorn/app/wsgiapp.py", line 58, in load
    return self.load_wsgiapp()
  File "/home/markbur@ilab.local/.local/share/virtualenvs/server-e9qqH9Aq/lib/python3.10/site-packages/gunicorn/app/wsgiapp.py", line 48, in load_wsgiapp
    return util.import_app(self.app_uri)
  File "/home/markbur@ilab.local/.local/share/virtualenvs/server-e9qqH9Aq/lib/python3.10/site-packages/gunicorn/util.py", line 371, in import_app
    mod = importlib.import_module(module)
  File "/usr/lib/python3.10/importlib/__init__.py", line 126, in import_module
    return _bootstrap._gcd_import(name[level:], package, level)
  File "<frozen importlib._bootstrap>", line 1050, in _gcd_import
  File "<frozen importlib._bootstrap>", line 1027, in _find_and_load
  File "<frozen importlib._bootstrap>", line 1006, in _find_and_load_unlocked
  File "<frozen importlib._bootstrap>", line 688, in _load_unlocked
  File "<frozen importlib._bootstrap_external>", line 883, in exec_module
  File "<frozen importlib._bootstrap>", line 241, in _call_with_frames_removed
  File "/home/markbur@ilab.local/sidekick/server/sidekick_server.py", line 54, in <module>
    app.config["JWT_SECRET_KEY"] = os.environ["JWT_SECRET"]
  File "/usr/lib/python3.10/os.py", line 680, in __getitem__
    raise KeyError(key) from None
KeyError: 'JWT_SECRET'
[2023-09-21 12:41:01 +0100] [1967803] [INFO] Worker exiting (pid: 1967803)
[2023-09-21 12:41:01 +0100] [1967798] [ERROR] Worker (pid:1967803) exited with code 3
[2023-09-21 12:41:01 +0100] [1967804] [ERROR] Exception in worker process
Traceback (most recent call last):
  File "/home/markbur@ilab.local/.local/share/virtualenvs/server-e9qqH9Aq/lib/python3.10/site-packages/gunicorn/arbiter.py", line 609, in spawn_worker
    worker.init_process()
  File "/home/markbur@ilab.local/.local/share/virtualenvs/server-e9qqH9Aq/lib/python3.10/site-packages/gunicorn/workers/base.py", line 134, in init_process
    self.load_wsgi()
  File "/home/markbur@ilab.local/.local/share/virtualenvs/server-e9qqH9Aq/lib/python3.10/site-packages/gunicorn/workers/base.py", line 146, in load_wsgi
    self.wsgi = self.app.wsgi()
  File "/home/markbur@ilab.local/.local/share/virtualenvs/server-e9qqH9Aq/lib/python3.10/site-packages/gunicorn/app/base.py", line 67, in wsgi
    self.callable = self.load()
  File "/home/markbur@ilab.local/.local/share/virtualenvs/server-e9qqH9Aq/lib/python3.10/site-packages/gunicorn/app/wsgiapp.py", line 58, in load
    return self.load_wsgiapp()
  File "/home/markbur@ilab.local/.local/share/virtualenvs/server-e9qqH9Aq/lib/python3.10/site-packages/gunicorn/app/wsgiapp.py", line 48, in load_wsgiapp
    return util.import_app(self.app_uri)
  File "/home/markbur@ilab.local/.local/share/virtualenvs/server-e9qqH9Aq/lib/python3.10/site-packages/gunicorn/util.py", line 371, in import_app
    mod = importlib.import_module(module)
  File "/usr/lib/python3.10/importlib/__init__.py", line 126, in import_module
    return _bootstrap._gcd_import(name[level:], package, level)
  File "<frozen importlib._bootstrap>", line 1050, in _gcd_import
  File "<frozen importlib._bootstrap>", line 1027, in _find_and_load
  File "<frozen importlib._bootstrap>", line 1006, in _find_and_load_unlocked
  File "<frozen importlib._bootstrap>", line 688, in _load_unlocked
  File "<frozen importlib._bootstrap_external>", line 883, in exec_module
  File "<frozen importlib._bootstrap>", line 241, in _call_with_frames_removed
  File "/home/markbur@ilab.local/sidekick/server/sidekick_server.py", line 54, in <module>
    app.config["JWT_SECRET_KEY"] = os.environ["JWT_SECRET"]
  File "/usr/lib/python3.10/os.py", line 680, in __getitem__
    raise KeyError(key) from None
KeyError: 'JWT_SECRET'
[2023-09-21 12:41:01 +0100] [1967804] [INFO] Worker exiting (pid: 1967804)
[2023-09-21 12:41:01 +0100] [1967798] [ERROR] Worker (pid:1967804) exited with code 3
Traceback (most recent call last):
  File "/home/markbur@ilab.local/.local/share/virtualenvs/server-e9qqH9Aq/lib/python3.10/site-packages/gunicorn/arbiter.py", line 209, in run
    self.sleep()
  File "/home/markbur@ilab.local/.local/share/virtualenvs/server-e9qqH9Aq/lib/python3.10/site-packages/gunicorn/arbiter.py", line 360, in sleep
    ready = select.select([self.PIPE[0]], [], [], 1.0)
  File "/home/markbur@ilab.local/.local/share/virtualenvs/server-e9qqH9Aq/lib/python3.10/site-packages/gunicorn/arbiter.py", line 242, in handle_chld
    self.reap_workers()
  File "/home/markbur@ilab.local/.local/share/virtualenvs/server-e9qqH9Aq/lib/python3.10/site-packages/gunicorn/arbiter.py", line 530, in reap_workers
    raise HaltServer(reason, self.WORKER_BOOT_ERROR)
gunicorn.errors.HaltServer: <HaltServer 'Worker failed to boot.' 3>

During handling of the above exception, another exception occurred:

Traceback (most recent call last):
  File "/home/markbur@ilab.local/.local/share/virtualenvs/server-e9qqH9Aq/bin/gunicorn", line 8, in <module>
    sys.exit(run())
  File "/home/markbur@ilab.local/.local/share/virtualenvs/server-e9qqH9Aq/lib/python3.10/site-packages/gunicorn/app/wsgiapp.py", line 67, in run
    WSGIApplication("%(prog)s [OPTIONS] [APP_MODULE]").run()
  File "/home/markbur@ilab.local/.local/share/virtualenvs/server-e9qqH9Aq/lib/python3.10/site-packages/gunicorn/app/base.py", line 236, in run
    super().run()
  File "/home/markbur@ilab.local/.local/share/virtualenvs/server-e9qqH9Aq/lib/python3.10/site-packages/gunicorn/app/base.py", line 72, in run
    Arbiter(self).run()
  File "/home/markbur@ilab.local/.local/share/virtualenvs/server-e9qqH9Aq/lib/python3.10/site-packages/gunicorn/arbiter.py", line 229, in run
    self.halt(reason=inst.reason, exit_status=inst.exit_status)
  File "/home/markbur@ilab.local/.local/share/virtualenvs/server-e9qqH9Aq/lib/python3.10/site-packages/gunicorn/arbiter.py", line 342, in halt
    self.stop()
  File "/home/markbur@ilab.local/.local/share/virtualenvs/server-e9qqH9Aq/lib/python3.10/site-packages/gunicorn/arbiter.py", line 396, in stop
    time.sleep(0.1)
  File "/home/markbur@ilab.local/.local/share/virtualenvs/server-e9qqH9Aq/lib/python3.10/site-packages/gunicorn/arbiter.py", line 242, in handle_chld
    self.reap_workers()
  File "/home/markbur@ilab.local/.local/share/virtualenvs/server-e9qqH9Aq/lib/python3.10/site-packages/gunicorn/arbiter.py", line 530, in reap_workers
    raise HaltServer(reason, self.WORKER_BOOT_ERROR)
gunicorn.errors.HaltServer: <HaltServer 'Worker failed to boot.' 3>
make: *** [Makefile:16: run-prod-locally] Error 1
[2023-09-21 12:41:01 +0100] [1967805] [ERROR] Exception in worker process
Traceback (most recent call last):
  File "/home/markbur@ilab.local/.local/share/virtualenvs/server-e9qqH9Aq/lib/python3.10/site-packages/gunicorn/arbiter.py", line 609, in spawn_worker
    worker.init_process()
  File "/home/markbur@ilab.local/.local/share/virtualenvs/server-e9qqH9Aq/lib/python3.10/site-packages/gunicorn/workers/base.py", line 134, in init_process
    self.load_wsgi()
  File "/home/markbur@ilab.local/.local/share/virtualenvs/server-e9qqH9Aq/lib/python3.10/site-packages/gunicorn/workers/base.py", line 146, in load_wsgi
    self.wsgi = self.app.wsgi()
  File "/home/markbur@ilab.local/.local/share/virtualenvs/server-e9qqH9Aq/lib/python3.10/site-packages/gunicorn/app/base.py", line 67, in wsgi
    self.callable = self.load()
  File "/home/markbur@ilab.local/.local/share/virtualenvs/server-e9qqH9Aq/lib/python3.10/site-packages/gunicorn/app/wsgiapp.py", line 58, in load
    return self.load_wsgiapp()
  File "/home/markbur@ilab.local/.local/share/virtualenvs/server-e9qqH9Aq/lib/python3.10/site-packages/gunicorn/app/wsgiapp.py", line 48, in load_wsgiapp
    return util.import_app(self.app_uri)
  File "/home/markbur@ilab.local/.local/share/virtualenvs/server-e9qqH9Aq/lib/python3.10/site-packages/gunicorn/util.py", line 371, in import_app
    mod = importlib.import_module(module)
  File "/usr/lib/python3.10/importlib/__init__.py", line 126, in import_module
    return _bootstrap._gcd_import(name[level:], package, level)
  File "<frozen importlib._bootstrap>", line 1050, in _gcd_import
  File "<frozen importlib._bootstrap>", line 1027, in _find_and_load
  File "<frozen importlib._bootstrap>", line 1006, in _find_and_load_unlocked
  File "<frozen importlib._bootstrap>", line 688, in _load_unlocked
  File "<frozen importlib._bootstrap_external>", line 883, in exec_module
  File "<frozen importlib._bootstrap>", line 241, in _call_with_frames_removed
  File "/home/markbur@ilab.local/sidekick/server/sidekick_server.py", line 54, in <module>
    app.config["JWT_SECRET_KEY"] = os.environ["JWT_SECRET"]
  File "/usr/lib/python3.10/os.py", line 680, in __getitem__
    raise KeyError(key) from None
KeyError: 'JWT_SECRET'
[2023-09-21 12:41:01 +0100] [1967805] [INFO] Worker exiting (pid: 1967805)
[2023-09-21 12:41:01 +0100] [1967806] [ERROR] Exception in worker process
Traceback (most recent call last):
  File "/home/markbur@ilab.local/.local/share/virtualenvs/server-e9qqH9Aq/lib/python3.10/site-packages/gunicorn/arbiter.py", line 609, in spawn_worker
    worker.init_process()
  File "/home/markbur@ilab.local/.local/share/virtualenvs/server-e9qqH9Aq/lib/python3.10/site-packages/gunicorn/workers/base.py", line 134, in init_process
    self.load_wsgi()
  File "/home/markbur@ilab.local/.local/share/virtualenvs/server-e9qqH9Aq/lib/python3.10/site-packages/gunicorn/workers/base.py", line 146, in load_wsgi
    self.wsgi = self.app.wsgi()
  File "/home/markbur@ilab.local/.local/share/virtualenvs/server-e9qqH9Aq/lib/python3.10/site-packages/gunicorn/app/base.py", line 67, in wsgi
    self.callable = self.load()
  File "/home/markbur@ilab.local/.local/share/virtualenvs/server-e9qqH9Aq/lib/python3.10/site-packages/gunicorn/app/wsgiapp.py", line 58, in load
    return self.load_wsgiapp()
  File "/home/markbur@ilab.local/.local/share/virtualenvs/server-e9qqH9Aq/lib/python3.10/site-packages/gunicorn/app/wsgiapp.py", line 48, in load_wsgiapp
    return util.import_app(self.app_uri)
  File "/home/markbur@ilab.local/.local/share/virtualenvs/server-e9qqH9Aq/lib/python3.10/site-packages/gunicorn/util.py", line 371, in import_app
    mod = importlib.import_module(module)
  File "/usr/lib/python3.10/importlib/__init__.py", line 126, in import_module
    return _bootstrap._gcd_import(name[level:], package, level)
  File "<frozen importlib._bootstrap>", line 1050, in _gcd_import
  File "<frozen importlib._bootstrap>", line 1027, in _find_and_load
  File "<frozen importlib._bootstrap>", line 1006, in _find_and_load_unlocked
  File "<frozen importlib._bootstrap>", line 688, in _load_unlocked
  File "<frozen importlib._bootstrap_external>", line 883, in exec_module
  File "<frozen importlib._bootstrap>", line 241, in _call_with_frames_removed
  File "/home/markbur@ilab.local/sidekick/server/sidekick_server.py", line 54, in <module>
    app.config["JWT_SECRET_KEY"] = os.environ["JWT_SECRET"]
  File "/usr/lib/python3.10/os.py", line 680, in __getitem__
    raise KeyError(key) from None
KeyError: 'JWT_SECRET'
[2023-09-21 12:41:01 +0100] [1967806] [INFO] Worker exiting (pid: 1967806)
pipenv run gunicorn -w 4 -b 0.0.0.0:5003 sidekick_server:app
Loading .env environment variables...
[2023-09-21 12:48:16 +0100] [1981728] [INFO] Starting gunicorn 21.2.0
[2023-09-21 12:48:16 +0100] [1981728] [INFO] Listening at: http://0.0.0.0:5003 (1981728)
[2023-09-21 12:48:16 +0100] [1981728] [INFO] Using worker: sync
[2023-09-21 12:48:16 +0100] [1981736] [INFO] Booting worker with pid: 1981736
[2023-09-21 12:48:17 +0100] [1981751] [INFO] Booting worker with pid: 1981751
[2023-09-21 12:48:17 +0100] [1981752] [INFO] Booting worker with pid: 1981752
[2023-09-21 12:48:17 +0100] [1981754] [INFO] Booting worker with pid: 1981754
[2023-09-21 12:48:17 +0100] [1981736] [ERROR] Exception in worker process
Traceback (most recent call last):
  File "/home/markbur@ilab.local/.local/share/virtualenvs/server-e9qqH9Aq/lib/python3.10/site-packages/gunicorn/arbiter.py", line 609, in spawn_worker
    worker.init_process()
  File "/home/markbur@ilab.local/.local/share/virtualenvs/server-e9qqH9Aq/lib/python3.10/site-packages/gunicorn/workers/base.py", line 134, in init_process
    self.load_wsgi()
  File "/home/markbur@ilab.local/.local/share/virtualenvs/server-e9qqH9Aq/lib/python3.10/site-packages/gunicorn/workers/base.py", line 146, in load_wsgi
    self.wsgi = self.app.wsgi()
  File "/home/markbur@ilab.local/.local/share/virtualenvs/server-e9qqH9Aq/lib/python3.10/site-packages/gunicorn/app/base.py", line 67, in wsgi
    self.callable = self.load()
  File "/home/markbur@ilab.local/.local/share/virtualenvs/server-e9qqH9Aq/lib/python3.10/site-packages/gunicorn/app/wsgiapp.py", line 58, in load
    return self.load_wsgiapp()
  File "/home/markbur@ilab.local/.local/share/virtualenvs/server-e9qqH9Aq/lib/python3.10/site-packages/gunicorn/app/wsgiapp.py", line 48, in load_wsgiapp
    return util.import_app(self.app_uri)
  File "/home/markbur@ilab.local/.local/share/virtualenvs/server-e9qqH9Aq/lib/python3.10/site-packages/gunicorn/util.py", line 371, in import_app
    mod = importlib.import_module(module)
  File "/usr/lib/python3.10/importlib/__init__.py", line 126, in import_module
    return _bootstrap._gcd_import(name[level:], package, level)
  File "<frozen importlib._bootstrap>", line 1050, in _gcd_import
  File "<frozen importlib._bootstrap>", line 1027, in _find_and_load
  File "<frozen importlib._bootstrap>", line 1006, in _find_and_load_unlocked
  File "<frozen importlib._bootstrap>", line 688, in _load_unlocked
  File "<frozen importlib._bootstrap_external>", line 883, in exec_module
  File "<frozen importlib._bootstrap>", line 241, in _call_with_frames_removed
  File "/home/markbur@ilab.local/sidekick/server/sidekick_server.py", line 85, in <module>
    _init_logger()
  File "/home/markbur@ilab.local/sidekick/server/sidekick_server.py", line 80, in _init_logger
    handler = RotatingFileHandler(os.path.join(config[LOGS_DIR_SETTING], PROGRAM_NAME + '.log'), maxBytes=1000000, backupCount=1)
  File "/usr/lib/python3.10/logging/handlers.py", line 155, in __init__
    BaseRotatingHandler.__init__(self, filename, mode, encoding=encoding,
  File "/usr/lib/python3.10/logging/handlers.py", line 58, in __init__
    logging.FileHandler.__init__(self, filename, mode=mode,
  File "/usr/lib/python3.10/logging/__init__.py", line 1169, in __init__
    StreamHandler.__init__(self, self._open())
  File "/usr/lib/python3.10/logging/__init__.py", line 1201, in _open
    return open_func(self.baseFilename, self.mode,
FileNotFoundError: [Errno 2] No such file or directory: '/home/markbur@ilab.local/sidekick/server/etc/logs/sidekick_server.log'
[2023-09-21 12:48:17 +0100] [1981736] [INFO] Worker exiting (pid: 1981736)
sidekick_server 0.0.0
Development mode disabled. To enable, export FLASK_ENV=development
[2023-09-21 12:48:17 +0100] [1981728] [ERROR] Worker (pid:1981736) exited with code 3
[2023-09-21 12:48:17 +0100] [1981751] [ERROR] Exception in worker process
Traceback (most recent call last):
  File "/home/markbur@ilab.local/.local/share/virtualenvs/server-e9qqH9Aq/lib/python3.10/site-packages/gunicorn/arbiter.py", line 609, in spawn_worker
    worker.init_process()
  File "/home/markbur@ilab.local/.local/share/virtualenvs/server-e9qqH9Aq/lib/python3.10/site-packages/gunicorn/workers/base.py", line 134, in init_process
    self.load_wsgi()
  File "/home/markbur@ilab.local/.local/share/virtualenvs/server-e9qqH9Aq/lib/python3.10/site-packages/gunicorn/workers/base.py", line 146, in load_wsgi
    self.wsgi = self.app.wsgi()
  File "/home/markbur@ilab.local/.local/share/virtualenvs/server-e9qqH9Aq/lib/python3.10/site-packages/gunicorn/app/base.py", line 67, in wsgi
    self.callable = self.load()
  File "/home/markbur@ilab.local/.local/share/virtualenvs/server-e9qqH9Aq/lib/python3.10/site-packages/gunicorn/app/wsgiapp.py", line 58, in load
    return self.load_wsgiapp()
  File "/home/markbur@ilab.local/.local/share/virtualenvs/server-e9qqH9Aq/lib/python3.10/site-packages/gunicorn/app/wsgiapp.py", line 48, in load_wsgiapp
    return util.import_app(self.app_uri)
  File "/home/markbur@ilab.local/.local/share/virtualenvs/server-e9qqH9Aq/lib/python3.10/site-packages/gunicorn/util.py", line 371, in import_app
    mod = importlib.import_module(module)
  File "/usr/lib/python3.10/importlib/__init__.py", line 126, in import_module
    return _bootstrap._gcd_import(name[level:], package, level)
  File "<frozen importlib._bootstrap>", line 1050, in _gcd_import
  File "<frozen importlib._bootstrap>", line 1027, in _find_and_load
  File "<frozen importlib._bootstrap>", line 1006, in _find_and_load_unlocked
  File "<frozen importlib._bootstrap>", line 688, in _load_unlocked
  File "<frozen importlib._bootstrap_external>", line 883, in exec_module
  File "<frozen importlib._bootstrap>", line 241, in _call_with_frames_removed
  File "/home/markbur@ilab.local/sidekick/server/sidekick_server.py", line 85, in <module>
    _init_logger()
  File "/home/markbur@ilab.local/sidekick/server/sidekick_server.py", line 80, in _init_logger
    handler = RotatingFileHandler(os.path.join(config[LOGS_DIR_SETTING], PROGRAM_NAME + '.log'), maxBytes=1000000, backupCount=1)
  File "/usr/lib/python3.10/logging/handlers.py", line 155, in __init__
    BaseRotatingHandler.__init__(self, filename, mode, encoding=encoding,
  File "/usr/lib/python3.10/logging/handlers.py", line 58, in __init__
    logging.FileHandler.__init__(self, filename, mode=mode,
  File "/usr/lib/python3.10/logging/__init__.py", line 1169, in __init__
    StreamHandler.__init__(self, self._open())
  File "/usr/lib/python3.10/logging/__init__.py", line 1201, in _open
    return open_func(self.baseFilename, self.mode,
FileNotFoundError: [Errno 2] No such file or directory: '/home/markbur@ilab.local/sidekick/server/etc/logs/sidekick_server.log'
[2023-09-21 12:48:17 +0100] [1981751] [INFO] Worker exiting (pid: 1981751)
sidekick_server 0.0.0
Development mode disabled. To enable, export FLASK_ENV=development
[2023-09-21 12:48:17 +0100] [1981752] [ERROR] Exception in worker process
Traceback (most recent call last):
  File "/home/markbur@ilab.local/.local/share/virtualenvs/server-e9qqH9Aq/lib/python3.10/site-packages/gunicorn/arbiter.py", line 609, in spawn_worker
    worker.init_process()
  File "/home/markbur@ilab.local/.local/share/virtualenvs/server-e9qqH9Aq/lib/python3.10/site-packages/gunicorn/workers/base.py", line 134, in init_process
    self.load_wsgi()
  File "/home/markbur@ilab.local/.local/share/virtualenvs/server-e9qqH9Aq/lib/python3.10/site-packages/gunicorn/workers/base.py", line 146, in load_wsgi
    self.wsgi = self.app.wsgi()
  File "/home/markbur@ilab.local/.local/share/virtualenvs/server-e9qqH9Aq/lib/python3.10/site-packages/gunicorn/app/base.py", line 67, in wsgi
    self.callable = self.load()
  File "/home/markbur@ilab.local/.local/share/virtualenvs/server-e9qqH9Aq/lib/python3.10/site-packages/gunicorn/app/wsgiapp.py", line 58, in load
    return self.load_wsgiapp()
  File "/home/markbur@ilab.local/.local/share/virtualenvs/server-e9qqH9Aq/lib/python3.10/site-packages/gunicorn/app/wsgiapp.py", line 48, in load_wsgiapp
    return util.import_app(self.app_uri)
  File "/home/markbur@ilab.local/.local/share/virtualenvs/server-e9qqH9Aq/lib/python3.10/site-packages/gunicorn/util.py", line 371, in import_app
    mod = importlib.import_module(module)
  File "/usr/lib/python3.10/importlib/__init__.py", line 126, in import_module
    return _bootstrap._gcd_import(name[level:], package, level)
  File "<frozen importlib._bootstrap>", line 1050, in _gcd_import
  File "<frozen importlib._bootstrap>", line 1027, in _find_and_load
  File "<frozen importlib._bootstrap>", line 1006, in _find_and_load_unlocked
  File "<frozen importlib._bootstrap>", line 688, in _load_unlocked
  File "<frozen importlib._bootstrap_external>", line 883, in exec_module
  File "<frozen importlib._bootstrap>", line 241, in _call_with_frames_removed
  File "/home/markbur@ilab.local/sidekick/server/sidekick_server.py", line 85, in <module>
    _init_logger()
  File "/home/markbur@ilab.local/sidekick/server/sidekick_server.py", line 80, in _init_logger
    handler = RotatingFileHandler(os.path.join(config[LOGS_DIR_SETTING], PROGRAM_NAME + '.log'), maxBytes=1000000, backupCount=1)
  File "/usr/lib/python3.10/logging/handlers.py", line 155, in __init__
    BaseRotatingHandler.__init__(self, filename, mode, encoding=encoding,
  File "/usr/lib/python3.10/logging/handlers.py", line 58, in __init__
    logging.FileHandler.__init__(self, filename, mode=mode,
  File "/usr/lib/python3.10/logging/__init__.py", line 1169, in __init__
    StreamHandler.__init__(self, self._open())
  File "/usr/lib/python3.10/logging/__init__.py", line 1201, in _open
    return open_func(self.baseFilename, self.mode,
FileNotFoundError: [Errno 2] No such file or directory: '/home/markbur@ilab.local/sidekick/server/etc/logs/sidekick_server.log'
[2023-09-21 12:48:17 +0100] [1981752] [INFO] Worker exiting (pid: 1981752)
sidekick_server 0.0.0
Development mode disabled. To enable, export FLASK_ENV=development
[2023-09-21 12:48:17 +0100] [1981728] [ERROR] Worker (pid:1981751) exited with code 3
Traceback (most recent call last):
  File "/home/markbur@ilab.local/.local/share/virtualenvs/server-e9qqH9Aq/lib/python3.10/site-packages/gunicorn/arbiter.py", line 202, in run
    self.manage_workers()
  File "/home/markbur@ilab.local/.local/share/virtualenvs/server-e9qqH9Aq/lib/python3.10/site-packages/gunicorn/arbiter.py", line 571, in manage_workers
    self.spawn_workers()
  File "/home/markbur@ilab.local/.local/share/virtualenvs/server-e9qqH9Aq/lib/python3.10/site-packages/gunicorn/arbiter.py", line 643, in spawn_workers
    time.sleep(0.1 * random.random())
  File "/home/markbur@ilab.local/.local/share/virtualenvs/server-e9qqH9Aq/lib/python3.10/site-packages/gunicorn/arbiter.py", line 242, in handle_chld
    self.reap_workers()
  File "/home/markbur@ilab.local/.local/share/virtualenvs/server-e9qqH9Aq/lib/python3.10/site-packages/gunicorn/arbiter.py", line 530, in reap_workers
    raise HaltServer(reason, self.WORKER_BOOT_ERROR)
gunicorn.errors.HaltServer: <HaltServer 'Worker failed to boot.' 3>

During handling of the above exception, another exception occurred:

Traceback (most recent call last):
  File "/home/markbur@ilab.local/.local/share/virtualenvs/server-e9qqH9Aq/bin/gunicorn", line 8, in <module>
    sys.exit(run())
  File "/home/markbur@ilab.local/.local/share/virtualenvs/server-e9qqH9Aq/lib/python3.10/site-packages/gunicorn/app/wsgiapp.py", line 67, in run
    WSGIApplication("%(prog)s [OPTIONS] [APP_MODULE]").run()
  File "/home/markbur@ilab.local/.local/share/virtualenvs/server-e9qqH9Aq/lib/python3.10/site-packages/gunicorn/app/base.py", line 236, in run
    super().run()
  File "/home/markbur@ilab.local/.local/share/virtualenvs/server-e9qqH9Aq/lib/python3.10/site-packages/gunicorn/app/base.py", line 72, in run
    Arbiter(self).run()
  File "/home/markbur@ilab.local/.local/share/virtualenvs/server-e9qqH9Aq/lib/python3.10/site-packages/gunicorn/arbiter.py", line 229, in run
    self.halt(reason=inst.reason, exit_status=inst.exit_status)
  File "/home/markbur@ilab.local/.local/share/virtualenvs/server-e9qqH9Aq/lib/python3.10/site-packages/gunicorn/arbiter.py", line 342, in halt
    self.stop()
  File "/home/markbur@ilab.local/.local/share/virtualenvs/server-e9qqH9Aq/lib/python3.10/site-packages/gunicorn/arbiter.py", line 396, in stop
    time.sleep(0.1)
  File "/home/markbur@ilab.local/.local/share/virtualenvs/server-e9qqH9Aq/lib/python3.10/site-packages/gunicorn/arbiter.py", line 242, in handle_chld
    self.reap_workers()
  File "/home/markbur@ilab.local/.local/share/virtualenvs/server-e9qqH9Aq/lib/python3.10/site-packages/gunicorn/arbiter.py", line 530, in reap_workers
    raise HaltServer(reason, self.WORKER_BOOT_ERROR)
gunicorn.errors.HaltServer: <HaltServer 'Worker failed to boot.' 3>
make: *** [Makefile:16: run-prod-locally] Error 1
[2023-09-21 12:48:17 +0100] [1981754] [ERROR] Exception in worker process
Traceback (most recent call last):
  File "/home/markbur@ilab.local/.local/share/virtualenvs/server-e9qqH9Aq/lib/python3.10/site-packages/gunicorn/arbiter.py", line 609, in spawn_worker
    worker.init_process()
  File "/home/markbur@ilab.local/.local/share/virtualenvs/server-e9qqH9Aq/lib/python3.10/site-packages/gunicorn/workers/base.py", line 134, in init_process
    self.load_wsgi()
  File "/home/markbur@ilab.local/.local/share/virtualenvs/server-e9qqH9Aq/lib/python3.10/site-packages/gunicorn/workers/base.py", line 146, in load_wsgi
    self.wsgi = self.app.wsgi()
  File "/home/markbur@ilab.local/.local/share/virtualenvs/server-e9qqH9Aq/lib/python3.10/site-packages/gunicorn/app/base.py", line 67, in wsgi
    self.callable = self.load()
  File "/home/markbur@ilab.local/.local/share/virtualenvs/server-e9qqH9Aq/lib/python3.10/site-packages/gunicorn/app/wsgiapp.py", line 58, in load
    return self.load_wsgiapp()
  File "/home/markbur@ilab.local/.local/share/virtualenvs/server-e9qqH9Aq/lib/python3.10/site-packages/gunicorn/app/wsgiapp.py", line 48, in load_wsgiapp
    return util.import_app(self.app_uri)
  File "/home/markbur@ilab.local/.local/share/virtualenvs/server-e9qqH9Aq/lib/python3.10/site-packages/gunicorn/util.py", line 371, in import_app
    mod = importlib.import_module(module)
  File "/usr/lib/python3.10/importlib/__init__.py", line 126, in import_module
    return _bootstrap._gcd_import(name[level:], package, level)
  File "<frozen importlib._bootstrap>", line 1050, in _gcd_import
  File "<frozen importlib._bootstrap>", line 1027, in _find_and_load
  File "<frozen importlib._bootstrap>", line 1006, in _find_and_load_unlocked
  File "<frozen importlib._bootstrap>", line 688, in _load_unlocked
  File "<frozen importlib._bootstrap_external>", line 883, in exec_module
  File "<frozen importlib._bootstrap>", line 241, in _call_with_frames_removed
  File "/home/markbur@ilab.local/sidekick/server/sidekick_server.py", line 85, in <module>
    _init_logger()
  File "/home/markbur@ilab.local/sidekick/server/sidekick_server.py", line 80, in _init_logger
    handler = RotatingFileHandler(os.path.join(config[LOGS_DIR_SETTING], PROGRAM_NAME + '.log'), maxBytes=1000000, backupCount=1)
  File "/usr/lib/python3.10/logging/handlers.py", line 155, in __init__
    BaseRotatingHandler.__init__(self, filename, mode, encoding=encoding,
  File "/usr/lib/python3.10/logging/handlers.py", line 58, in __init__
    logging.FileHandler.__init__(self, filename, mode=mode,
  File "/usr/lib/python3.10/logging/__init__.py", line 1169, in __init__
    StreamHandler.__init__(self, self._open())
  File "/usr/lib/python3.10/logging/__init__.py", line 1201, in _open
    return open_func(self.baseFilename, self.mode,
FileNotFoundError: [Errno 2] No such file or directory: '/home/markbur@ilab.local/sidekick/server/etc/logs/sidekick_server.log'
[2023-09-21 12:48:17 +0100] [1981754] [INFO] Worker exiting (pid: 1981754)
sidekick_server 0.0.0
Development mode disabled. To enable, export FLASK_ENV=development
pipenv run gunicorn -w 4 -b 0.0.0.0:5003 sidekick_server:app
Loading .env environment variables...
[2023-09-21 12:50:06 +0100] [1984923] [INFO] Starting gunicorn 21.2.0
[2023-09-21 12:50:06 +0100] [1984923] [INFO] Listening at: http://0.0.0.0:5003 (1984923)
[2023-09-21 12:50:06 +0100] [1984923] [INFO] Using worker: sync
[2023-09-21 12:50:06 +0100] [1985039] [INFO] Booting worker with pid: 1985039
[2023-09-21 12:50:06 +0100] [1985041] [INFO] Booting worker with pid: 1985041
[2023-09-21 12:50:06 +0100] [1985042] [INFO] Booting worker with pid: 1985042
[2023-09-21 12:50:06 +0100] [1985044] [INFO] Booting worker with pid: 1985044
